[2023-10-01T10:57:53.751+0000] {taskinstance.py:1171} INFO - Dependencies all met for <TaskInstance: TEST1_M3_Data_Pipeline.get_data_from_postgresql manual__2023-10-01T10:57:51.859492+00:00 [queued]>
[2023-10-01T10:57:53.765+0000] {taskinstance.py:1171} INFO - Dependencies all met for <TaskInstance: TEST1_M3_Data_Pipeline.get_data_from_postgresql manual__2023-10-01T10:57:51.859492+00:00 [queued]>
[2023-10-01T10:57:53.766+0000] {taskinstance.py:1368} INFO - 
--------------------------------------------------------------------------------
[2023-10-01T10:57:53.767+0000] {taskinstance.py:1369} INFO - Starting attempt 1 of 2
[2023-10-01T10:57:53.768+0000] {taskinstance.py:1370} INFO - 
--------------------------------------------------------------------------------
[2023-10-01T10:57:53.786+0000] {taskinstance.py:1389} INFO - Executing <Task(PythonOperator): get_data_from_postgresql> on 2023-10-01 10:57:51.859492+00:00
[2023-10-01T10:57:53.794+0000] {standard_task_runner.py:52} INFO - Started process 431 to run task
[2023-10-01T10:57:53.798+0000] {standard_task_runner.py:79} INFO - Running: ['***', 'tasks', 'run', 'TEST1_M3_Data_Pipeline', 'get_data_from_postgresql', 'manual__2023-10-01T10:57:51.859492+00:00', '--job-id', '4', '--raw', '--subdir', 'DAGS_FOLDER/P2M3_Rivaldi_Valensia_DAG.py', '--cfg-path', '/tmp/tmp8tc9kk44', '--error-file', '/tmp/tmp1sk8uaxr']
[2023-10-01T10:57:53.801+0000] {standard_task_runner.py:80} INFO - Job 4: Subtask get_data_from_postgresql
[2023-10-01T10:57:53.891+0000] {task_command.py:371} INFO - Running <TaskInstance: TEST1_M3_Data_Pipeline.get_data_from_postgresql manual__2023-10-01T10:57:51.859492+00:00 [running]> on host 301507a0fc69
[2023-10-01T10:57:53.990+0000] {taskinstance.py:1583} INFO - Exporting the following env vars:
AIRFLOW_CTX_DAG_OWNER=***
AIRFLOW_CTX_DAG_ID=TEST1_M3_Data_Pipeline
AIRFLOW_CTX_TASK_ID=get_data_from_postgresql
AIRFLOW_CTX_EXECUTION_DATE=2023-10-01T10:57:51.859492+00:00
AIRFLOW_CTX_TRY_NUMBER=1
AIRFLOW_CTX_DAG_RUN_ID=manual__2023-10-01T10:57:51.859492+00:00
[2023-10-01T10:57:53.998+0000] {taskinstance.py:1902} ERROR - Task failed with exception
Traceback (most recent call last):
  File "/home/airflow/.local/lib/python3.7/site-packages/pandas/io/sql.py", line 2056, in execute
    cur.execute(*args, **kwargs)
psycopg2.errors.UndefinedTable: relation "table_m3" does not exist
LINE 1: select * from table_M3
                      ^


The above exception was the direct cause of the following exception:

Traceback (most recent call last):
  File "/home/airflow/.local/lib/python3.7/site-packages/airflow/operators/python.py", line 171, in execute
    return_value = self.execute_callable()
  File "/home/airflow/.local/lib/python3.7/site-packages/airflow/operators/python.py", line 189, in execute_callable
    return self.python_callable(*self.op_args, **self.op_kwargs)
  File "/opt/airflow/dags/P2M3_Rivaldi_Valensia_DAG.py", line 24, in get_data_from_postgresql
    df = pd.read_sql("select * from table_M3", conn)  # Updated table name to 'table_m3'
  File "/home/airflow/.local/lib/python3.7/site-packages/pandas/io/sql.py", line 608, in read_sql
    chunksize=chunksize,
  File "/home/airflow/.local/lib/python3.7/site-packages/pandas/io/sql.py", line 2116, in read_query
    cursor = self.execute(*args)
  File "/home/airflow/.local/lib/python3.7/site-packages/pandas/io/sql.py", line 2068, in execute
    raise ex from exc
pandas.io.sql.DatabaseError: Execution failed on sql 'select * from table_M3': relation "table_m3" does not exist
LINE 1: select * from table_M3
                      ^

[2023-10-01T10:57:54.013+0000] {taskinstance.py:1412} INFO - Marking task as UP_FOR_RETRY. dag_id=TEST1_M3_Data_Pipeline, task_id=get_data_from_postgresql, execution_date=20231001T105751, start_date=20231001T105753, end_date=20231001T105754
[2023-10-01T10:57:54.029+0000] {standard_task_runner.py:97} ERROR - Failed to execute job 4 for task get_data_from_postgresql (Execution failed on sql 'select * from table_M3': relation "table_m3" does not exist
LINE 1: select * from table_M3
                      ^
; 431)
[2023-10-01T10:57:54.053+0000] {local_task_job.py:156} INFO - Task exited with return code 1
[2023-10-01T10:57:54.115+0000] {local_task_job.py:279} INFO - 0 downstream tasks scheduled from follow-on schedule check
