[2023-09-29T12:20:12.253+0000] {taskinstance.py:1171} INFO - Dependencies all met for <TaskInstance: data_pipeline.fetch_postgresql_data manual__2023-09-29T12:15:02.398868+00:00 [queued]>
[2023-09-29T12:20:12.267+0000] {taskinstance.py:1171} INFO - Dependencies all met for <TaskInstance: data_pipeline.fetch_postgresql_data manual__2023-09-29T12:15:02.398868+00:00 [queued]>
[2023-09-29T12:20:12.268+0000] {taskinstance.py:1368} INFO - 
--------------------------------------------------------------------------------
[2023-09-29T12:20:12.269+0000] {taskinstance.py:1369} INFO - Starting attempt 2 of 2
[2023-09-29T12:20:12.270+0000] {taskinstance.py:1370} INFO - 
--------------------------------------------------------------------------------
[2023-09-29T12:20:12.289+0000] {taskinstance.py:1389} INFO - Executing <Task(PythonOperator): fetch_postgresql_data> on 2023-09-29 12:15:02.398868+00:00
[2023-09-29T12:20:12.297+0000] {standard_task_runner.py:52} INFO - Started process 366 to run task
[2023-09-29T12:20:12.302+0000] {standard_task_runner.py:79} INFO - Running: ['***', 'tasks', 'run', 'data_pipeline', 'fetch_postgresql_data', 'manual__2023-09-29T12:15:02.398868+00:00', '--job-id', '4', '--raw', '--subdir', 'DAGS_FOLDER/P2M3_Rivaldi_Valensia_DAG.py', '--cfg-path', '/tmp/tmp7qymcfrf', '--error-file', '/tmp/tmp7qq1gu8z']
[2023-09-29T12:20:12.311+0000] {standard_task_runner.py:80} INFO - Job 4: Subtask fetch_postgresql_data
[2023-09-29T12:20:12.406+0000] {task_command.py:371} INFO - Running <TaskInstance: data_pipeline.fetch_postgresql_data manual__2023-09-29T12:15:02.398868+00:00 [running]> on host 418d8312d32a
[2023-09-29T12:20:12.523+0000] {taskinstance.py:1583} INFO - Exporting the following env vars:
AIRFLOW_CTX_DAG_OWNER=***
AIRFLOW_CTX_DAG_ID=data_pipeline
AIRFLOW_CTX_TASK_ID=fetch_postgresql_data
AIRFLOW_CTX_EXECUTION_DATE=2023-09-29T12:15:02.398868+00:00
AIRFLOW_CTX_TRY_NUMBER=2
AIRFLOW_CTX_DAG_RUN_ID=manual__2023-09-29T12:15:02.398868+00:00
[2023-09-29T12:20:12.529+0000] {taskinstance.py:1902} ERROR - Task failed with exception
Traceback (most recent call last):
  File "/home/airflow/.local/lib/python3.7/site-packages/airflow/operators/python.py", line 171, in execute
    return_value = self.execute_callable()
  File "/home/airflow/.local/lib/python3.7/site-packages/airflow/operators/python.py", line 189, in execute_callable
    return self.python_callable(*self.op_args, **self.op_kwargs)
  File "/opt/airflow/dags/P2M3_Rivaldi_Valensia_DAG.py", line 12, in fetch_postgresql_data
    conn = db.connect(conn_string)
  File "/home/airflow/.local/lib/python3.7/site-packages/psycopg2/__init__.py", line 122, in connect
    conn = _connect(dsn, connection_factory=connection_factory, **kwasync)
psycopg2.OperationalError: connection to server at "localhost" (127.0.0.1), port 5432 failed: Connection refused
	Is the server running on that host and accepting TCP/IP connections?
connection to server at "localhost" (::1), port 5432 failed: Cannot assign requested address
	Is the server running on that host and accepting TCP/IP connections?

[2023-09-29T12:20:12.552+0000] {taskinstance.py:1412} INFO - Marking task as FAILED. dag_id=data_pipeline, task_id=fetch_postgresql_data, execution_date=20230929T121502, start_date=20230929T122012, end_date=20230929T122012
[2023-09-29T12:20:12.576+0000] {standard_task_runner.py:97} ERROR - Failed to execute job 4 for task fetch_postgresql_data (connection to server at "localhost" (127.0.0.1), port 5432 failed: Connection refused
	Is the server running on that host and accepting TCP/IP connections?
connection to server at "localhost" (::1), port 5432 failed: Cannot assign requested address
	Is the server running on that host and accepting TCP/IP connections?
; 366)
[2023-09-29T12:20:12.596+0000] {local_task_job.py:156} INFO - Task exited with return code 1
[2023-09-29T12:20:12.662+0000] {local_task_job.py:279} INFO - 0 downstream tasks scheduled from follow-on schedule check
