[2023-10-01T11:31:47.770+0000] {taskinstance.py:1171} INFO - Dependencies all met for <TaskInstance: Valdi_Pipeline.get_data_from_postgresql manual__2023-10-01T11:31:45.520154+00:00 [queued]>
[2023-10-01T11:31:47.791+0000] {taskinstance.py:1171} INFO - Dependencies all met for <TaskInstance: Valdi_Pipeline.get_data_from_postgresql manual__2023-10-01T11:31:45.520154+00:00 [queued]>
[2023-10-01T11:31:47.792+0000] {taskinstance.py:1368} INFO - 
--------------------------------------------------------------------------------
[2023-10-01T11:31:47.793+0000] {taskinstance.py:1369} INFO - Starting attempt 1 of 2
[2023-10-01T11:31:47.794+0000] {taskinstance.py:1370} INFO - 
--------------------------------------------------------------------------------
[2023-10-01T11:31:47.836+0000] {taskinstance.py:1389} INFO - Executing <Task(PythonOperator): get_data_from_postgresql> on 2023-10-01 11:31:45.520154+00:00
[2023-10-01T11:31:47.847+0000] {standard_task_runner.py:52} INFO - Started process 214 to run task
[2023-10-01T11:31:47.852+0000] {standard_task_runner.py:79} INFO - Running: ['***', 'tasks', 'run', 'Valdi_Pipeline', 'get_data_from_postgresql', 'manual__2023-10-01T11:31:45.520154+00:00', '--job-id', '2', '--raw', '--subdir', 'DAGS_FOLDER/P2M3_Rivaldi_Valensia_DAG.py', '--cfg-path', '/tmp/tmpuc0k5pe5', '--error-file', '/tmp/tmpudushfdc']
[2023-10-01T11:31:47.855+0000] {standard_task_runner.py:80} INFO - Job 2: Subtask get_data_from_postgresql
[2023-10-01T11:31:47.952+0000] {task_command.py:371} INFO - Running <TaskInstance: Valdi_Pipeline.get_data_from_postgresql manual__2023-10-01T11:31:45.520154+00:00 [running]> on host aede7beb5ed8
[2023-10-01T11:31:48.055+0000] {taskinstance.py:1583} INFO - Exporting the following env vars:
AIRFLOW_CTX_DAG_OWNER=Valdi
AIRFLOW_CTX_DAG_ID=Valdi_Pipeline
AIRFLOW_CTX_TASK_ID=get_data_from_postgresql
AIRFLOW_CTX_EXECUTION_DATE=2023-10-01T11:31:45.520154+00:00
AIRFLOW_CTX_TRY_NUMBER=1
AIRFLOW_CTX_DAG_RUN_ID=manual__2023-10-01T11:31:45.520154+00:00
[2023-10-01T11:31:48.063+0000] {taskinstance.py:1902} ERROR - Task failed with exception
Traceback (most recent call last):
  File "/home/airflow/.local/lib/python3.7/site-packages/pandas/io/sql.py", line 2056, in execute
    cur.execute(*args, **kwargs)
psycopg2.errors.UndefinedTable: relation "public.table_m3" does not exist
LINE 1: select * from public.table_m3
                      ^


The above exception was the direct cause of the following exception:

Traceback (most recent call last):
  File "/home/airflow/.local/lib/python3.7/site-packages/airflow/operators/python.py", line 171, in execute
    return_value = self.execute_callable()
  File "/home/airflow/.local/lib/python3.7/site-packages/airflow/operators/python.py", line 189, in execute_callable
    return self.python_callable(*self.op_args, **self.op_kwargs)
  File "/opt/airflow/dags/P2M3_Rivaldi_Valensia_DAG.py", line 24, in get_data_from_postgresql
    df = pd.read_sql("select * from public.table_m3", conn)  # Updated table name to 'public.table_m3'
  File "/home/airflow/.local/lib/python3.7/site-packages/pandas/io/sql.py", line 608, in read_sql
    chunksize=chunksize,
  File "/home/airflow/.local/lib/python3.7/site-packages/pandas/io/sql.py", line 2116, in read_query
    cursor = self.execute(*args)
  File "/home/airflow/.local/lib/python3.7/site-packages/pandas/io/sql.py", line 2068, in execute
    raise ex from exc
pandas.io.sql.DatabaseError: Execution failed on sql 'select * from public.table_m3': relation "public.table_m3" does not exist
LINE 1: select * from public.table_m3
                      ^

[2023-10-01T11:31:48.082+0000] {taskinstance.py:1412} INFO - Marking task as UP_FOR_RETRY. dag_id=Valdi_Pipeline, task_id=get_data_from_postgresql, execution_date=20231001T113145, start_date=20231001T113147, end_date=20231001T113148
[2023-10-01T11:31:48.098+0000] {standard_task_runner.py:97} ERROR - Failed to execute job 2 for task get_data_from_postgresql (Execution failed on sql 'select * from public.table_m3': relation "public.table_m3" does not exist
LINE 1: select * from public.table_m3
                      ^
; 214)
[2023-10-01T11:31:48.148+0000] {local_task_job.py:156} INFO - Task exited with return code 1
[2023-10-01T11:31:48.215+0000] {local_task_job.py:279} INFO - 0 downstream tasks scheduled from follow-on schedule check
