[2023-10-01T10:54:26.537+0000] {taskinstance.py:1171} INFO - Dependencies all met for <TaskInstance: P2M3_Valdi_Data_Pipeline.connect_postgres manual__2023-10-01T10:54:21.635127+00:00 [queued]>
[2023-10-01T10:54:26.552+0000] {taskinstance.py:1171} INFO - Dependencies all met for <TaskInstance: P2M3_Valdi_Data_Pipeline.connect_postgres manual__2023-10-01T10:54:21.635127+00:00 [queued]>
[2023-10-01T10:54:26.553+0000] {taskinstance.py:1368} INFO - 
--------------------------------------------------------------------------------
[2023-10-01T10:54:26.554+0000] {taskinstance.py:1369} INFO - Starting attempt 1 of 2
[2023-10-01T10:54:26.555+0000] {taskinstance.py:1370} INFO - 
--------------------------------------------------------------------------------
[2023-10-01T10:54:26.575+0000] {taskinstance.py:1389} INFO - Executing <Task(PostgresOperator): connect_postgres> on 2023-10-01 10:54:21.635127+00:00
[2023-10-01T10:54:26.586+0000] {standard_task_runner.py:52} INFO - Started process 331 to run task
[2023-10-01T10:54:26.592+0000] {standard_task_runner.py:79} INFO - Running: ['***', 'tasks', 'run', 'P2M3_Valdi_Data_Pipeline', 'connect_postgres', 'manual__2023-10-01T10:54:21.635127+00:00', '--job-id', '3', '--raw', '--subdir', 'DAGS_FOLDER/P2M3_Rivaldi_Valensia_DAG.py', '--cfg-path', '/tmp/tmpl1rtsn8i', '--error-file', '/tmp/tmpu55g0uzw']
[2023-10-01T10:54:26.597+0000] {standard_task_runner.py:80} INFO - Job 3: Subtask connect_postgres
[2023-10-01T10:54:26.718+0000] {task_command.py:371} INFO - Running <TaskInstance: P2M3_Valdi_Data_Pipeline.connect_postgres manual__2023-10-01T10:54:21.635127+00:00 [running]> on host 301507a0fc69
[2023-10-01T10:54:26.767+0000] {taskinstance.py:1902} ERROR - Task failed with exception
Traceback (most recent call last):
  File "/home/airflow/.local/lib/python3.7/site-packages/airflow/models/taskinstance.py", line 1463, in _run_raw_task
    self._execute_task_with_callbacks(context, test_mode)
  File "/home/airflow/.local/lib/python3.7/site-packages/airflow/models/taskinstance.py", line 1567, in _execute_task_with_callbacks
    task_orig = self.render_templates(context=context)
  File "/home/airflow/.local/lib/python3.7/site-packages/airflow/models/taskinstance.py", line 2225, in render_templates
    rendered_task = self.task.render_template_fields(context)
  File "/home/airflow/.local/lib/python3.7/site-packages/airflow/models/baseoperator.py", line 1188, in render_template_fields
    self._do_render_template_fields(self, self.template_fields, context, jinja_env, set())
  File "/home/airflow/.local/lib/python3.7/site-packages/airflow/utils/session.py", line 71, in wrapper
    return func(*args, session=session, **kwargs)
  File "/home/airflow/.local/lib/python3.7/site-packages/airflow/models/abstractoperator.py", line 347, in _do_render_template_fields
    seen_oids,
  File "/home/airflow/.local/lib/python3.7/site-packages/airflow/models/abstractoperator.py", line 384, in render_template
    template = jinja_env.get_template(value)
  File "/home/airflow/.local/lib/python3.7/site-packages/jinja2/environment.py", line 1010, in get_template
    return self._load_template(name, globals)
  File "/home/airflow/.local/lib/python3.7/site-packages/jinja2/environment.py", line 969, in _load_template
    template = self.loader.load(self, name, self.make_globals(globals))
  File "/home/airflow/.local/lib/python3.7/site-packages/jinja2/loaders.py", line 126, in load
    source, filename, uptodate = self.get_source(environment, name)
  File "/home/airflow/.local/lib/python3.7/site-packages/jinja2/loaders.py", line 218, in get_source
    raise TemplateNotFound(template)
jinja2.exceptions.TemplateNotFound: dags/sql/P2M3_Rivaldi_Valensia_ddl.sql
[2023-10-01T10:54:26.791+0000] {taskinstance.py:1412} INFO - Marking task as UP_FOR_RETRY. dag_id=P2M3_Valdi_Data_Pipeline, task_id=connect_postgres, execution_date=20231001T105421, start_date=20231001T105426, end_date=20231001T105426
[2023-10-01T10:54:26.811+0000] {standard_task_runner.py:97} ERROR - Failed to execute job 3 for task connect_postgres (dags/sql/P2M3_Rivaldi_Valensia_ddl.sql; 331)
[2023-10-01T10:54:26.847+0000] {local_task_job.py:156} INFO - Task exited with return code 1
[2023-10-01T10:54:26.915+0000] {local_task_job.py:279} INFO - 0 downstream tasks scheduled from follow-on schedule check
