[2023-10-03T10:33:22.707+0000] {taskinstance.py:1171} INFO - Dependencies all met for <TaskInstance: Valdi_Pipeline.get_data_from_postgresql scheduled__2023-10-02T00:00:00+00:00 [queued]>
[2023-10-03T10:33:22.720+0000] {taskinstance.py:1171} INFO - Dependencies all met for <TaskInstance: Valdi_Pipeline.get_data_from_postgresql scheduled__2023-10-02T00:00:00+00:00 [queued]>
[2023-10-03T10:33:22.721+0000] {taskinstance.py:1368} INFO - 
--------------------------------------------------------------------------------
[2023-10-03T10:33:22.722+0000] {taskinstance.py:1369} INFO - Starting attempt 1 of 2
[2023-10-03T10:33:22.723+0000] {taskinstance.py:1370} INFO - 
--------------------------------------------------------------------------------
[2023-10-03T10:33:22.744+0000] {taskinstance.py:1389} INFO - Executing <Task(PythonOperator): get_data_from_postgresql> on 2023-10-02 00:00:00+00:00
[2023-10-03T10:33:22.758+0000] {standard_task_runner.py:52} INFO - Started process 216 to run task
[2023-10-03T10:33:22.767+0000] {standard_task_runner.py:79} INFO - Running: ['***', 'tasks', 'run', 'Valdi_Pipeline', 'get_data_from_postgresql', 'scheduled__2023-10-02T00:00:00+00:00', '--job-id', '2', '--raw', '--subdir', 'DAGS_FOLDER/P2M3_Rivaldi_Valensia_DAG.py', '--cfg-path', '/tmp/tmprzgd21mb', '--error-file', '/tmp/tmppuque6bl']
[2023-10-03T10:33:22.774+0000] {standard_task_runner.py:80} INFO - Job 2: Subtask get_data_from_postgresql
[2023-10-03T10:33:23.115+0000] {task_command.py:371} INFO - Running <TaskInstance: Valdi_Pipeline.get_data_from_postgresql scheduled__2023-10-02T00:00:00+00:00 [running]> on host e86848fd619c
[2023-10-03T10:33:23.374+0000] {taskinstance.py:1583} INFO - Exporting the following env vars:
AIRFLOW_CTX_DAG_OWNER=Valdi
AIRFLOW_CTX_DAG_ID=Valdi_Pipeline
AIRFLOW_CTX_TASK_ID=get_data_from_postgresql
AIRFLOW_CTX_EXECUTION_DATE=2023-10-02T00:00:00+00:00
AIRFLOW_CTX_TRY_NUMBER=1
AIRFLOW_CTX_DAG_RUN_ID=scheduled__2023-10-02T00:00:00+00:00
[2023-10-03T10:33:23.381+0000] {taskinstance.py:1902} ERROR - Task failed with exception
Traceback (most recent call last):
  File "/home/airflow/.local/lib/python3.7/site-packages/airflow/operators/python.py", line 171, in execute
    return_value = self.execute_callable()
  File "/home/airflow/.local/lib/python3.7/site-packages/airflow/operators/python.py", line 189, in execute_callable
    return self.python_callable(*self.op_args, **self.op_kwargs)
  File "/opt/airflow/dags/P2M3_Rivaldi_Valensia_DAG.py", line 23, in get_data_from_postgresql
    conn = db.connect(conn_string)
  File "/home/airflow/.local/lib/python3.7/site-packages/psycopg2/__init__.py", line 122, in connect
    conn = _connect(dsn, connection_factory=connection_factory, **kwasync)
psycopg2.OperationalError: connection to server at "postgres" (172.20.0.3), port 5432 failed: FATAL:  database "db_phase2" does not exist

[2023-10-03T10:33:23.398+0000] {taskinstance.py:1412} INFO - Marking task as UP_FOR_RETRY. dag_id=Valdi_Pipeline, task_id=get_data_from_postgresql, execution_date=20231002T000000, start_date=20231003T103322, end_date=20231003T103323
[2023-10-03T10:33:23.415+0000] {standard_task_runner.py:97} ERROR - Failed to execute job 2 for task get_data_from_postgresql (connection to server at "postgres" (172.20.0.3), port 5432 failed: FATAL:  database "db_phase2" does not exist
; 216)
[2023-10-03T10:33:23.463+0000] {local_task_job.py:156} INFO - Task exited with return code 1
[2023-10-03T10:33:23.524+0000] {local_task_job.py:279} INFO - 0 downstream tasks scheduled from follow-on schedule check
