[2023-10-02T03:43:10.475+0000] {taskinstance.py:1171} INFO - Dependencies all met for <TaskInstance: Valdi_LC8.cleaning_data manual__2023-10-02T03:42:57.818290+00:00 [queued]>
[2023-10-02T03:43:10.520+0000] {taskinstance.py:1171} INFO - Dependencies all met for <TaskInstance: Valdi_LC8.cleaning_data manual__2023-10-02T03:42:57.818290+00:00 [queued]>
[2023-10-02T03:43:10.522+0000] {taskinstance.py:1368} INFO - 
--------------------------------------------------------------------------------
[2023-10-02T03:43:10.525+0000] {taskinstance.py:1369} INFO - Starting attempt 1 of 2
[2023-10-02T03:43:10.527+0000] {taskinstance.py:1370} INFO - 
--------------------------------------------------------------------------------
[2023-10-02T03:43:10.593+0000] {taskinstance.py:1389} INFO - Executing <Task(PythonOperator): cleaning_data> on 2023-10-02 03:42:57.818290+00:00
[2023-10-02T03:43:10.609+0000] {standard_task_runner.py:52} INFO - Started process 232 to run task
[2023-10-02T03:43:10.618+0000] {standard_task_runner.py:79} INFO - Running: ['***', 'tasks', 'run', 'Valdi_LC8', 'cleaning_data', 'manual__2023-10-02T03:42:57.818290+00:00', '--job-id', '19', '--raw', '--subdir', 'DAGS_FOLDER/P2G8_Rivaldi_Valensia_DAG.py', '--cfg-path', '/tmp/tmpxh88x6q3', '--error-file', '/tmp/tmp54u_nrug']
[2023-10-02T03:43:10.634+0000] {standard_task_runner.py:80} INFO - Job 19: Subtask cleaning_data
[2023-10-02T03:43:11.147+0000] {task_command.py:371} INFO - Running <TaskInstance: Valdi_LC8.cleaning_data manual__2023-10-02T03:42:57.818290+00:00 [running]> on host 5f5d0b98abe4
[2023-10-02T03:43:11.478+0000] {taskinstance.py:1583} INFO - Exporting the following env vars:
AIRFLOW_CTX_DAG_OWNER=Valdi
AIRFLOW_CTX_DAG_ID=Valdi_LC8
AIRFLOW_CTX_TASK_ID=cleaning_data
AIRFLOW_CTX_EXECUTION_DATE=2023-10-02T03:42:57.818290+00:00
AIRFLOW_CTX_TRY_NUMBER=1
AIRFLOW_CTX_DAG_RUN_ID=manual__2023-10-02T03:42:57.818290+00:00
[2023-10-02T03:43:11.487+0000] {taskinstance.py:1902} ERROR - Task failed with exception
Traceback (most recent call last):
  File "/home/airflow/.local/lib/python3.7/site-packages/airflow/operators/python.py", line 171, in execute
    return_value = self.execute_callable()
  File "/home/airflow/.local/lib/python3.7/site-packages/airflow/operators/python.py", line 189, in execute_callable
    return self.python_callable(*self.op_args, **self.op_kwargs)
TypeError: cleaning_data() missing 1 required positional argument: 'df'
[2023-10-02T03:43:11.521+0000] {taskinstance.py:1412} INFO - Marking task as UP_FOR_RETRY. dag_id=Valdi_LC8, task_id=cleaning_data, execution_date=20231002T034257, start_date=20231002T034310, end_date=20231002T034311
[2023-10-02T03:43:11.547+0000] {standard_task_runner.py:97} ERROR - Failed to execute job 19 for task cleaning_data (cleaning_data() missing 1 required positional argument: 'df'; 232)
[2023-10-02T03:43:11.577+0000] {local_task_job.py:156} INFO - Task exited with return code 1
[2023-10-02T03:43:11.704+0000] {local_task_job.py:279} INFO - 0 downstream tasks scheduled from follow-on schedule check
